<?xml version="1.0" ?>
<!-- =================================================================================== -->
<!-- |    This document was autogenerated by xacro from curiosity_mars_rover.xacro     | -->
<!-- |    EDITING THIS FILE BY HAND IS NOT RECOMMENDED                                 | -->
<!-- =================================================================================== -->
<robot name="curiosity_mars_rover">
  <gazebo>
    <plugin filename="libign_ros2_control-system" name="ign_ros2_control::IgnitionROS2ControlPlugin">
      <robot_param>robot_description</robot_param>
      <robot_param_node>robot_state_publisher</robot_param_node>
      <parameters>/home/spaceros-user/demos_ws/install/mars_rover/share/mars_rover/config/mars_rover_controller_effort.yaml</parameters>
    </plugin>
    <plugin filename="ignition-gazebo-odometry-publisher-system" name="ignition::gazebo::systems::OdometryPublisher">
      <odom_frame>/odom</odom_frame>
      <robot_base_frame>/base_footprint</robot_base_frame>
      <odom_publish_frequency>10</odom_publish_frequency>
    </plugin>
    <plugin filename="ignition-gazebo-sensors-system" name="ignition::gazebo::systems::Sensors">
      <render_engine>ogre2</render_engine>
      <background_color>0.9 0.753 0.66 1</background_color>
    </plugin>
  </gazebo>
  <gazebo reference="lidar_link">
    <sensor name="lidar" type="gpu_lidar">
      &quot;
          
      <ignition_frame_id>lidar_link</ignition_frame_id>
      <pose relative_to="lidar_link">0 0 0 0 0 0</pose>
      <topic>scan</topic>
      <update_rate>10</update_rate>
      <ray>
        <scan>
          <horizontal>
            <samples>640</samples>
            <resolution>1</resolution>
            <min_angle>-3.1416</min_angle>
            <max_angle>3.1416</max_angle>
          </horizontal>
          <vertical>
            <samples>1</samples>
            <resolution>0.01</resolution>
            <min_angle>0</min_angle>
            <max_angle>0</max_angle>
          </vertical>
        </scan>
        <range>
          <min>1.0</min>
          <max>20.0</max>
          <resolution>0.05</resolution>
        </range>
      </ray>
      <always_on>1</always_on>
      <visualize>true</visualize>
    </sensor>
  </gazebo>
  <gazebo reference="camera_link">
    <sensor name="camera_sensor" type="camera">
      <visualize>1</visualize>
      <update_rate>10.0</update_rate>
      <camera>
        <pose>1.0 0 0 0 0 -1.57</pose>
        <horizontal_fov>1.3962634</horizontal_fov>
        <image>
          <width>800</width>
          <height>800</height>
          <format>R8G8B8</format>
        </image>
        <clip>
          <near>0.01</near>
          <far>100</far>
        </clip>
        <noise>
          <type>gaussian</type>
          <stddev>0.007</stddev>
        </noise>
      </camera>
      <always_on>1</always_on>
      <topic>image_raw</topic>
    </sensor>
  </gazebo>
  <!-- Chassis -->
  <gazebo reference="chassis">
    <mu1>0.3</mu1>
    <mu2>0.3</mu2>
  </gazebo>
  <!-- Wheel Train -->
  <gazebo reference="left_axis">
    <mu1>0.3</mu1>
    <mu2>0.3</mu2>
  </gazebo>
  <gazebo reference="suspension_arm_F_L">
    <mu1>0.3</mu1>
    <mu2>0.3</mu2>
  </gazebo>
  <gazebo reference="right_axis">
    <mu1>0.3</mu1>
    <mu2>0.3</mu2>
  </gazebo>
  <gazebo reference="suspension_arm_F_R">
    <mu1>0.3</mu1>
    <mu2>0.3</mu2>
  </gazebo>
  <gazebo reference="suspension_arm_B_L">
    <mu1>0.3</mu1>
    <mu2>0.3</mu2>
  </gazebo>
  <gazebo reference="suspension_arm_B_R">
    <mu1>0.3</mu1>
    <mu2>0.3</mu2>
  </gazebo>
  <gazebo reference="suspension_arm_B_L_to_B2_L">
    <mu1>0.3</mu1>
    <mu2>0.3</mu2>
    <material>Gazebo/Black</material>
  </gazebo>
  <gazebo reference="suspension_arm_B_R_to_B2_R">
    <mu1>0.3</mu1>
    <mu2>0.3</mu2>
    <material>Gazebo/Black</material>
  </gazebo>
  <gazebo reference="suspension_arm_B2_L">
    <mu1>0.3</mu1>
    <mu2>0.3</mu2>
  </gazebo>
  <gazebo reference="suspension_arm_B2_R">
    <mu1>0.3</mu1>
    <mu2>0.3</mu2>
  </gazebo>
  <gazebo reference="suspension_arm_F_L_to_suspension_steer_F_L">
    <mu1>0.3</mu1>
    <mu2>0.3</mu2>
  </gazebo>
  <gazebo reference="suspension_arm_F_R_to_suspension_steer_F_R">
    <mu1>0.3</mu1>
    <mu2>0.3</mu2>
  </gazebo>
  <gazebo reference="suspension_steer_F_L">
    <mu1>0.3</mu1>
    <mu2>0.3</mu2>
  </gazebo>
  <gazebo reference="suspension_steer_F_R">
    <mu1>0.3</mu1>
    <mu2>0.3</mu2>
  </gazebo>
  <gazebo reference="suspension_arm_B2_L_to_suspension_steer_B_L">
    <mu1>0.3</mu1>
    <mu2>0.3</mu2>
  </gazebo>
  <gazebo reference="suspension_arm_B2_R_to_suspension_steer_B_R">
    <mu1>0.3</mu1>
    <mu2>0.3</mu2>
  </gazebo>
  <gazebo reference="suspension_steer_B_L">
    <mu1>0.3</mu1>
    <mu2>0.3</mu2>
  </gazebo>
  <gazebo reference="suspension_steer_B_R">
    <mu1>0.3</mu1>
    <mu2>0.3</mu2>
  </gazebo>
  <!-- Arm -->
  <gazebo reference="arm_01">
    <mu1>0.3</mu1>
    <mu2>0.3</mu2>
  </gazebo>
  <!-- Used for fixing robot to Gazebo 'chassis' -->
  <link name="base_footprint"/>
  <link name="base_link"/>
  <joint name="base_footprint_to_link" type="fixed">
    <parent link="base_footprint"/>
    <child link="base_link"/>
  </joint>
  <joint name="base_to_chassis" type="fixed">
    <parent link="base_link"/>
    <child link="chassis"/>
    <origin rpy="0 0 1.57" xyz="0 0 0"/>
  </joint>
  <link name="chassis">
    <collision>
      <origin rpy="0 0 0" xyz="0 0 0"/>
      <geometry>
        <mesh filename="package://mppi_controller/models/curiosity/meshes/chassis_full_fixed_glitch_v2.dae" scale="1.0 1.0 1.0"/>
      </geometry>
    </collision>
    <visual>
      <origin rpy="0 0 0" xyz="0 0 0"/>
      <geometry>
        <mesh filename="package://mppi_controller/models/curiosity/meshes/chassis_full_fixed_glitch_v2.dae" scale="1.0 1.0 1.0"/>
      </geometry>
    </visual>
    <inertial>
      <origin rpy="0 0 0" xyz="0 0 0"/>
      <mass value="733.64"/>
      <inertia ixx="300.2136598264364" ixy="0" ixz="0" iyy="179.87900948563868" iyz="0" izz="409.4675919787417"/>
    </inertial>
  </link>
  <link name="left_axis">
    <collision>
      <origin rpy="0 0 0" xyz="0 0 0"/>
      <geometry>
        <mesh filename="package://mppi_controller/models/curiosity/meshes/left_axis_jointfix_v2.dae" scale="1.0 1.0 1.0"/>
      </geometry>
    </collision>
    <visual>
      <origin rpy="0 0 0" xyz="0 0 0"/>
      <geometry>
        <mesh filename="package://mppi_controller/models/curiosity/meshes/left_axis_jointfix_v2.dae" scale="1.0 1.0 1.0"/>
      </geometry>
    </visual>
    <inertial>
      <origin rpy="0 0 0" xyz="0 0 0"/>
      <mass value="7.295999999999999"/>
      <inertia ixx="0.105611398768" ixy="0" ixz="0" iyy="0.12505778379519997" iyz="0" izz="0.0696602588128"/>
    </inertial>
  </link>
  <joint name="left_axis_joint" type="fixed">
    <parent link="chassis"/>
    <child link="left_axis"/>
    <origin rpy="0 -0.19565141 0" xyz="0.7938 -0.2133 0"/>
  </joint>
  <link name="suspension_arm_F_L">
    <collision>
      <origin rpy="0 0 0" xyz="0 0 0"/>
      <geometry>
        <mesh filename="package://mppi_controller/models/curiosity/meshes/suspension_arm_F_L_fixed.dae" scale="1.0 1.0 1.0"/>
      </geometry>
    </collision>
    <visual>
      <origin rpy="0 0 0" xyz="0 0 0"/>
      <geometry>
        <mesh filename="package://mppi_controller/models/curiosity/meshes/suspension_arm_F_L_fixed.dae" scale="1.0 1.0 1.0"/>
      </geometry>
    </visual>
    <inertial>
      <origin rpy="0 0 0" xyz="0 0 0"/>
      <mass value="7.295999999999999"/>
      <inertia ixx="0.691776350704" ixy="0" ixz="0" iyy="0.1520658179456" iyz="0" izz="0.730456577456"/>
    </inertial>
  </link>
  <joint name="suspension_arm_F_L_joint" type="revolute">
    <parent link="left_axis"/>
    <child link="suspension_arm_F_L"/>
    <origin rpy="0 0 0" xyz="0 0 0"/>
    <limit effort="10000.0" lower="-0.4" upper="0.4" velocity="10.0"/>
    <axis xyz="1 0 0"/>
    <dynamics damping="0.5" friction="0.5"/>
  </joint>
  <link name="suspension_arm_B_L">
    <collision>
      <origin rpy="0 0 0" xyz="0 0 0"/>
      <geometry>
        <mesh filename="package://mppi_controller/models/curiosity/meshes/suspension_arm_B_L_fixed.dae" scale="1.0 1.0 1.0"/>
      </geometry>
    </collision>
    <visual>
      <origin rpy="0 0 0" xyz="0 0 0"/>
      <geometry>
        <mesh filename="package://mppi_controller/models/curiosity/meshes/suspension_arm_B_L_fixed.dae" scale="1.0 1.0 1.0"/>
      </geometry>
    </visual>
    <inertial>
      <origin rpy="0 0 0" xyz="0 0 0"/>
      <mass value="7.295999999999999"/>
      <inertia ixx="0.5152426402118399" ixy="0" ixz="0" iyy="0.083058082238336" iyz="0" izz="0.45073850312191993"/>
    </inertial>
  </link>
  <joint name="suspension_arm_B_L_joint" type="revolute">
    <parent link="left_axis"/>
    <child link="suspension_arm_B_L"/>
    <origin rpy="0 0 0" xyz="0 0 0"/>
    <limit effort="10000.0" lower="-0.4" upper="0.4" velocity="10.0"/>
    <axis xyz="1 0 0"/>
    <dynamics damping="0.5" friction="0.5"/>
  </joint>
  <link name="suspension_arm_B_L_to_B2_L">
    <inertial>
      <origin rpy="0 0 0" xyz="0 0 0"/>
      <mass value="0.02"/>
      <inertia ixx="2.61666666667e-05" ixy="0.0" ixz="0.0" iyy="2.61666666667e-05" iyz="0.0" izz="3.6e-05"/>
    </inertial>
    <collision>
      <origin rpy="0 0 0" xyz="0 0 0.015"/>
      <geometry>
        <cylinder length="0.035" radius="0.06"/>
      </geometry>
    </collision>
    <visual>
      <origin rpy="0.0 1.57 0" xyz="0 0 0"/>
      <geometry>
        <cylinder length="0.1" radius="0.04"/>
      </geometry>
    </visual>
  </link>
  <joint name="suspension_arm_B_L_to_B2_L_joint" type="fixed">
    <parent link="suspension_arm_B_L"/>
    <child link="suspension_arm_B_L_to_B2_L"/>
    <origin rpy="0 0.1937315 0" xyz="-0.05159 0.73683 -0.22972"/>
  </joint>
  <link name="suspension_arm_B2_L">
    <collision>
      <origin rpy="0 0 0" xyz="0 0 0"/>
      <geometry>
        <mesh filename="package://mppi_controller/models/curiosity/meshes/suspension_arm_B2_L_fixed.dae" scale="1.0 1.0 1.0"/>
      </geometry>
    </collision>
    <visual>
      <origin rpy="0 0 0" xyz="0 0 0"/>
      <geometry>
        <mesh filename="package://mppi_controller/models/curiosity/meshes/suspension_arm_B2_L_fixed.dae" scale="1.0 1.0 1.0"/>
      </geometry>
    </visual>
    <inertial>
      <origin rpy="0 0 0" xyz="0 0 0"/>
      <mass value="7.295999999999999"/>
      <inertia ixx="1.1489656574635518" ixy="0" ixz="0" iyy="0.33974878204390385" iyz="0" izz="1.004031832490752"/>
    </inertial>
  </link>
  <joint name="suspension_arm_B2_L_joint" type="revolute">
    <parent link="suspension_arm_B_L_to_B2_L"/>
    <child link="suspension_arm_B2_L"/>
    <origin rpy="0 0 0" xyz="0 0 0"/>
    <limit effort="10000.0" lower="-1.2" upper="1.2" velocity="10.0"/>
    <axis xyz="1 0 0"/>
    <dynamics damping="0.5" friction="0.5"/>
  </joint>
  <!-- FRONT WHEEL -->
  <link name="suspension_arm_F_L_to_suspension_steer_F_L">
    <inertial>
      <origin rpy="0 0 0" xyz="0 0 0"/>
      <mass value="0.02"/>
      <inertia ixx="2.61666666667e-05" ixy="0.0" ixz="0.0" iyy="2.61666666667e-05" iyz="0.0" izz="3.6e-05"/>
    </inertial>
    <collision>
      <origin rpy="0 0 0" xyz="0 0 0.015"/>
      <geometry>
        <cylinder length="0.04" radius="0.06"/>
      </geometry>
    </collision>
    <visual>
      <origin rpy="0.0 0 0" xyz="0 0 0"/>
      <geometry>
        <cylinder length="0.04" radius="0.06"/>
      </geometry>
    </visual>
  </link>
  <joint name="suspension_arm_F_L_to_suspension_steer_F_L_joint" type="fixed">
    <parent link="suspension_arm_F_L"/>
    <child link="suspension_arm_F_L_to_suspension_steer_F_L"/>
    <origin rpy="0 0.1937315 0" xyz="0.2057 -0.87876 -0.29370"/>
  </joint>
  <link name="suspension_steer_F_L">
    <collision>
      <origin rpy="0 0 0" xyz="0 0 0"/>
      <geometry>
        <mesh filename="package://mppi_controller/models/curiosity/meshes/suspension_steer_F_L_fixed.dae" scale="1.0 1.0 1.0"/>
      </geometry>
    </collision>
    <visual>
      <origin rpy="0 0 0" xyz="0 0 0"/>
      <geometry>
        <mesh filename="package://mppi_controller/models/curiosity/meshes/suspension_steer_F_L_fixed.dae" scale="1.0 1.0 1.0"/>
      </geometry>
    </visual>
    <inertial>
      <origin rpy="0 0 0" xyz="0 0 0"/>
      <mass value="7.295999999999999"/>
      <inertia ixx="0.150001040336768" ixy="0" ixz="0" iyy="0.2928966459341759" iyz="0" izz="0.19661828629500797"/>
    </inertial>
  </link>
  <joint name="suspension_steer_F_L_joint" type="revolute">
    <parent link="suspension_arm_F_L_to_suspension_steer_F_L"/>
    <child link="suspension_steer_F_L"/>
    <origin rpy="0 0 0" xyz="0 0 0"/>
    <limit effort="10000.0" lower="-0.6" upper="0.6" velocity="10.0"/>
    <axis xyz="0 0 1"/>
  </joint>
  <link name="suspension_steer_F_L_to_front_wheel_L">
    <inertial>
      <origin rpy="0 0 0" xyz="0 0 0"/>
      <mass value="0.02"/>
      <inertia ixx="2.61666666667e-05" ixy="0.0" ixz="0.0" iyy="2.61666666667e-05" iyz="0.0" izz="3.6e-05"/>
    </inertial>
    <collision>
      <origin rpy="0.0 1.57 0" xyz="0 0 0"/>
      <geometry>
        <cylinder length="0.02" radius="0.02"/>
      </geometry>
    </collision>
    <visual>
      <origin rpy="0.0 1.57 0" xyz="0 0 0"/>
      <geometry>
        <cylinder length="0.02" radius="0.02"/>
      </geometry>
    </visual>
  </link>
  <joint name="suspension_steer_F_L_to_suspension_steer_F_L_to_front_wheel_L_joint" type="fixed">
    <parent link="suspension_steer_F_L"/>
    <child link="suspension_steer_F_L_to_front_wheel_L"/>
    <origin rpy="0 0 0" xyz="0 0 -0.3996"/>
  </joint>
  <!-- tY is Zero if left side, 1 if right side -->
  <link name="front_wheel_L">
    <collision>
      <origin rpy="0 1.57 0" xyz="0 0 0"/>
      <geometry>
        <cylinder length="0.39473" radius="0.242647"/>
      </geometry>
    </collision>
    <visual>
      <origin rpy="0 0 0" xyz="0 0 0"/>
      <geometry>
        <mesh filename="package://mppi_controller/models/curiosity/meshes/wheel_fixed.dae" scale="1.0 1.0 1.0"/>
      </geometry>
    </visual>
    <inertial>
      <origin rpy="0 0 0" xyz="0 0 0"/>
      <mass value="2.07"/>
      <inertia ixx="0.05734667154540749" ixy="0" ixz="0" iyy="0.05734667154540749" iyz="0" izz="0.06093828144031499"/>
    </inertial>
  </link>
  <gazebo reference="front_wheel_L">
    <mu1 value="1.0"/>
    <mu2 value="1.0"/>
    <kp value="10000000.0"/>
    <kd>100.0</kd>
    <minDepth>0.001</minDepth>
    <maxVel>1.0</maxVel>
    <!--kd  value="1.0" />
      <fdir1 value="1 0 0"/-->
  </gazebo>
  <joint name="front_wheel_L_joint" type="continuous">
    <parent link="suspension_steer_F_L_to_front_wheel_L"/>
    <child link="front_wheel_L"/>
    <origin rpy="0 0 0.0" xyz="0 0 0"/>
    <limit effort="10000.0" velocity="100.0"/>
    <axis xyz="1 0 0"/>
    <dynamics damping="0.0" friction="0.0"/>
  </joint>
  <!-- FRONT LEFT Wheel Left END -->
  <!-- MIDDLE WHEEL -->
  <link name="suspension_arm_B2_L_to_middle_wheel_L">
    <inertial>
      <origin rpy="0 0 0" xyz="0 0 0"/>
      <mass value="0.02"/>
      <inertia ixx="2.61666666667e-05" ixy="0.0" ixz="0.0" iyy="2.61666666667e-05" iyz="0.0" izz="3.6e-05"/>
    </inertial>
    <collision>
      <origin rpy="0.0 1.57 0" xyz="0 0 0"/>
      <geometry>
        <cylinder length="0.02" radius="0.02"/>
      </geometry>
    </collision>
    <visual>
      <origin rpy="0.0 1.57 0" xyz="0 0 0"/>
      <geometry>
        <cylinder length="0.02" radius="0.02"/>
      </geometry>
    </visual>
  </link>
  <joint name="suspension_arm_B2_L_to_suspension_arm_B2_L_to_middle_wheel_L_joint" type="fixed">
    <parent link="suspension_arm_B2_L"/>
    <child link="suspension_arm_B2_L_to_middle_wheel_L"/>
    <origin rpy="0 0 0" xyz="0.39423 -0.44859 -0.41098"/>
  </joint>
  <!-- tY is Zero if left side, 1 if right side -->
  <link name="middle_wheel_L">
    <collision>
      <origin rpy="0 1.57 0" xyz="0 0 0"/>
      <geometry>
        <cylinder length="0.39473" radius="0.242647"/>
      </geometry>
    </collision>
    <visual>
      <origin rpy="0 0 0" xyz="0 0 0"/>
      <geometry>
        <mesh filename="package://mppi_controller/models/curiosity/meshes/wheel_fixed.dae" scale="1.0 1.0 1.0"/>
      </geometry>
    </visual>
    <inertial>
      <origin rpy="0 0 0" xyz="0 0 0"/>
      <mass value="2.07"/>
      <inertia ixx="0.05734667154540749" ixy="0" ixz="0" iyy="0.05734667154540749" iyz="0" izz="0.06093828144031499"/>
    </inertial>
  </link>
  <gazebo reference="middle_wheel_L">
    <mu1 value="1.0"/>
    <mu2 value="1.0"/>
    <kp value="10000000.0"/>
    <kd>100.0</kd>
    <minDepth>0.001</minDepth>
    <maxVel>1.0</maxVel>
    <!--kd  value="1.0" />
      <fdir1 value="1 0 0"/-->
  </gazebo>
  <joint name="middle_wheel_L_joint" type="continuous">
    <parent link="suspension_arm_B2_L_to_middle_wheel_L"/>
    <child link="middle_wheel_L"/>
    <origin rpy="0 0 0.0" xyz="0 0 0"/>
    <limit effort="10000.0" velocity="100.0"/>
    <axis xyz="1 0 0"/>
    <dynamics damping="0.0" friction="0.0"/>
  </joint>
  <!-- FRONT MIDDLE Wheel Left END -->
  <!-- BACK WHEEL -->
  <link name="suspension_arm_B2_L_to_suspension_steer_B_L">
    <inertial>
      <origin rpy="0 0 0" xyz="0 0 0"/>
      <mass value="0.02"/>
      <inertia ixx="2.61666666667e-05" ixy="0.0" ixz="0.0" iyy="2.61666666667e-05" iyz="0.0" izz="3.6e-05"/>
    </inertial>
    <collision>
      <origin rpy="0 0 0" xyz="0 0 0.015"/>
      <geometry>
        <cylinder length="0.04" radius="0.06"/>
      </geometry>
    </collision>
    <visual>
      <origin rpy="0.0 0 0" xyz="0 0 0"/>
      <geometry>
        <cylinder length="0.04" radius="0.06"/>
      </geometry>
    </visual>
  </link>
  <joint name="suspension_arm_B2_L_to_suspension_steer_B_L_joint" type="fixed">
    <parent link="suspension_arm_B2_L"/>
    <child link="suspension_arm_B2_L_to_suspension_steer_B_L"/>
    <origin rpy="0 0 0" xyz="0.26271 0.62363 -0.00069"/>
  </joint>
  <link name="suspension_steer_B_L">
    <collision>
      <origin rpy="0 0 0" xyz="0 0 0"/>
      <geometry>
        <mesh filename="package://mppi_controller/models/curiosity/meshes/suspension_steer_B_L_fixed.dae" scale="1.0 1.0 1.0"/>
      </geometry>
    </collision>
    <visual>
      <origin rpy="0 0 0" xyz="0 0 0"/>
      <geometry>
        <mesh filename="package://mppi_controller/models/curiosity/meshes/suspension_steer_B_L_fixed.dae" scale="1.0 1.0 1.0"/>
      </geometry>
    </visual>
    <inertial>
      <origin rpy="0 0 0" xyz="0 0 0"/>
      <mass value="7.295999999999999"/>
      <inertia ixx="0.150001040336768" ixy="0" ixz="0" iyy="0.2928966459341759" iyz="0" izz="0.19661828629500797"/>
    </inertial>
  </link>
  <joint name="suspension_steer_B_L_joint" type="revolute">
    <parent link="suspension_arm_B2_L_to_suspension_steer_B_L"/>
    <child link="suspension_steer_B_L"/>
    <origin rpy="0 0 0" xyz="0 0 0"/>
    <limit effort="10000.0" lower="-0.6" upper="0.6" velocity="10.0"/>
    <axis xyz="0 0 1"/>
  </joint>
  <link name="suspension_steer_B_L_to_back_wheel_L">
    <inertial>
      <origin rpy="0 0 0" xyz="0 0 0"/>
      <mass value="0.02"/>
      <inertia ixx="2.61666666667e-05" ixy="0.0" ixz="0.0" iyy="2.61666666667e-05" iyz="0.0" izz="3.6e-05"/>
    </inertial>
    <collision>
      <origin rpy="0.0 1.57 0" xyz="0 0 0"/>
      <geometry>
        <cylinder length="0.02" radius="0.02"/>
      </geometry>
    </collision>
    <visual>
      <origin rpy="0.0 1.57 0" xyz="0 0 0"/>
      <geometry>
        <cylinder length="0.02" radius="0.02"/>
      </geometry>
    </visual>
  </link>
  <joint name="suspension_arm_B2_L_to_suspension_steer_B_L_to_back_wheel_L_joint" type="fixed">
    <parent link="suspension_steer_B_L"/>
    <child link="suspension_steer_B_L_to_back_wheel_L"/>
    <origin rpy="0 0 0" xyz="0 0 -0.410523"/>
  </joint>
  <!-- tY is Zero if left side, 1 if right side -->
  <link name="back_wheel_L">
    <collision>
      <origin rpy="0 1.57 0" xyz="0 0 0"/>
      <geometry>
        <cylinder length="0.39473" radius="0.242647"/>
      </geometry>
    </collision>
    <visual>
      <origin rpy="0 0 0" xyz="0 0 0"/>
      <geometry>
        <mesh filename="package://mppi_controller/models/curiosity/meshes/wheel_fixed.dae" scale="1.0 1.0 1.0"/>
      </geometry>
    </visual>
    <inertial>
      <origin rpy="0 0 0" xyz="0 0 0"/>
      <mass value="2.07"/>
      <inertia ixx="0.05734667154540749" ixy="0" ixz="0" iyy="0.05734667154540749" iyz="0" izz="0.06093828144031499"/>
    </inertial>
  </link>
  <gazebo reference="back_wheel_L">
    <mu1 value="1.0"/>
    <mu2 value="1.0"/>
    <kp value="10000000.0"/>
    <kd>100.0</kd>
    <minDepth>0.001</minDepth>
    <maxVel>1.0</maxVel>
    <!--kd  value="1.0" />
      <fdir1 value="1 0 0"/-->
  </gazebo>
  <joint name="back_wheel_L_joint" type="continuous">
    <parent link="suspension_steer_B_L_to_back_wheel_L"/>
    <child link="back_wheel_L"/>
    <origin rpy="0 0 0.0" xyz="0 0 0"/>
    <limit effort="10000.0" velocity="100.0"/>
    <axis xyz="1 0 0"/>
    <dynamics damping="0.0" friction="0.0"/>
  </joint>
  <!-- END BACK WHEEL LEFT -->
  <link name="right_axis">
    <collision>
      <origin rpy="0 0 0" xyz="0 0 0"/>
      <geometry>
        <mesh filename="package://mppi_controller/models/curiosity/meshes/right_axis_jointfix_v2.dae" scale="1.0 1.0 1.0"/>
      </geometry>
    </collision>
    <visual>
      <origin rpy="0 0 0" xyz="0 0 0"/>
      <geometry>
        <mesh filename="package://mppi_controller/models/curiosity/meshes/right_axis_jointfix_v2.dae" scale="1.0 1.0 1.0"/>
      </geometry>
    </visual>
    <inertial>
      <origin rpy="0 0 0" xyz="0 0 0"/>
      <mass value="7.295999999999999"/>
      <inertia ixx="0.105611398768" ixy="0" ixz="0" iyy="0.12505778379519997" iyz="0" izz="0.0696602588128"/>
    </inertial>
  </link>
  <joint name="right_axis_joint" type="fixed">
    <parent link="chassis"/>
    <child link="right_axis"/>
    <origin rpy="0 0.19565141 0" xyz="-0.7938 -0.2133 0"/>
  </joint>
  <link name="suspension_arm_F_R">
    <collision>
      <origin rpy="0 0 0" xyz="0 0 0"/>
      <geometry>
        <mesh filename="package://mppi_controller/models/curiosity/meshes/suspension_arm_F_R_fixed.dae" scale="1.0 1.0 1.0"/>
      </geometry>
    </collision>
    <visual>
      <origin rpy="0 0 0" xyz="0 0 0"/>
      <geometry>
        <mesh filename="package://mppi_controller/models/curiosity/meshes/suspension_arm_F_R_fixed.dae" scale="1.0 1.0 1.0"/>
      </geometry>
    </visual>
    <inertial>
      <origin rpy="0 0 0" xyz="0 0 0"/>
      <mass value="7.295999999999999"/>
      <inertia ixx="0.691776350704" ixy="0" ixz="0" iyy="0.1520658179456" iyz="0" izz="0.730456577456"/>
    </inertial>
  </link>
  <joint name="suspension_arm_F_R_joint" type="revolute">
    <parent link="right_axis"/>
    <child link="suspension_arm_F_R"/>
    <origin rpy="0 0 0" xyz="0 0 0"/>
    <limit effort="10000.0" lower="-0.4" upper="0.4" velocity="10.0"/>
    <axis xyz="1 0 0"/>
    <dynamics damping="0.5" friction="0.5"/>
  </joint>
  <link name="suspension_arm_B_R">
    <collision>
      <origin rpy="0 0 0" xyz="0 0 0"/>
      <geometry>
        <mesh filename="package://mppi_controller/models/curiosity/meshes/suspension_arm_B_R_fixed.dae" scale="1.0 1.0 1.0"/>
      </geometry>
    </collision>
    <visual>
      <origin rpy="0 0 0" xyz="0 0 0"/>
      <geometry>
        <mesh filename="package://mppi_controller/models/curiosity/meshes/suspension_arm_B_R_fixed.dae" scale="1.0 1.0 1.0"/>
      </geometry>
    </visual>
    <inertial>
      <origin rpy="0 0 0" xyz="0 0 0"/>
      <mass value="7.295999999999999"/>
      <inertia ixx="0.5152426402118399" ixy="0" ixz="0" iyy="0.083058082238336" iyz="0" izz="0.45073850312191993"/>
    </inertial>
  </link>
  <joint name="suspension_arm_B_R_joint" type="revolute">
    <parent link="right_axis"/>
    <child link="suspension_arm_B_R"/>
    <origin rpy="0 0 0" xyz="0 0 0"/>
    <limit effort="10000.0" lower="-0.4" upper="0.4" velocity="10.0"/>
    <axis xyz="1 0 0"/>
    <dynamics damping="0.5" friction="0.5"/>
  </joint>
  <link name="suspension_arm_B_R_to_B2_R">
    <inertial>
      <origin rpy="0 0 0" xyz="0 0 0"/>
      <mass value="0.02"/>
      <inertia ixx="2.61666666667e-05" ixy="0.0" ixz="0.0" iyy="2.61666666667e-05" iyz="0.0" izz="3.6e-05"/>
    </inertial>
    <collision>
      <origin rpy="0 0 0" xyz="0 0 0.015"/>
      <geometry>
        <cylinder length="0.035" radius="0.06"/>
      </geometry>
    </collision>
    <visual>
      <origin rpy="0.0 1.57 0" xyz="0 0 0"/>
      <geometry>
        <cylinder length="0.1" radius="0.04"/>
      </geometry>
    </visual>
  </link>
  <joint name="suspension_arm_B_R_to_B2_R_joint" type="fixed">
    <parent link="suspension_arm_B_R"/>
    <child link="suspension_arm_B_R_to_B2_R"/>
    <origin rpy="0 -0.1937315 0" xyz="0.05159 0.73683 -0.22972"/>
  </joint>
  <link name="suspension_arm_B2_R">
    <collision>
      <origin rpy="0 0 0" xyz="0 0 0"/>
      <geometry>
        <mesh filename="package://mppi_controller/models/curiosity/meshes/suspension_arm_B2_R_fixed.dae" scale="1.0 1.0 1.0"/>
      </geometry>
    </collision>
    <visual>
      <origin rpy="0 0 0" xyz="0 0 0"/>
      <geometry>
        <mesh filename="package://mppi_controller/models/curiosity/meshes/suspension_arm_B2_R_fixed.dae" scale="1.0 1.0 1.0"/>
      </geometry>
    </visual>
    <inertial>
      <origin rpy="0 0 0" xyz="0 0 0"/>
      <mass value="7.295999999999999"/>
      <inertia ixx="1.1489656574635518" ixy="0" ixz="0" iyy="0.33974878204390385" iyz="0" izz="1.004031832490752"/>
    </inertial>
  </link>
  <joint name="suspension_arm_B2_R_joint" type="revolute">
    <parent link="suspension_arm_B_R_to_B2_R"/>
    <child link="suspension_arm_B2_R"/>
    <origin rpy="0 0 0" xyz="0 0 0"/>
    <limit effort="10000.0" lower="-1.2" upper="1.2" velocity="10.0"/>
    <axis xyz="1 0 0"/>
    <dynamics damping="0.5" friction="0.5"/>
  </joint>
  <!-- FRONT WHEEL RIGHT -->
  <link name="suspension_arm_F_R_to_suspension_steer_F_R">
    <inertial>
      <origin rpy="0 0 0" xyz="0 0 0"/>
      <mass value="0.02"/>
      <inertia ixx="2.61666666667e-05" ixy="0.0" ixz="0.0" iyy="2.61666666667e-05" iyz="0.0" izz="3.6e-05"/>
    </inertial>
    <collision>
      <origin rpy="0 0 0" xyz="0 0 0.015"/>
      <geometry>
        <cylinder length="0.04" radius="0.06"/>
      </geometry>
    </collision>
    <visual>
      <origin rpy="0.0 0 0" xyz="0 0 0"/>
      <geometry>
        <cylinder length="0.04" radius="0.06"/>
      </geometry>
    </visual>
  </link>
  <joint name="suspension_arm_F_R_to_suspension_steer_F_R_joint" type="fixed">
    <parent link="suspension_arm_F_R"/>
    <child link="suspension_arm_F_R_to_suspension_steer_F_R"/>
    <origin rpy="0 -0.1937315 0" xyz="-0.2057 -0.87876 -0.29370"/>
  </joint>
  <link name="suspension_steer_F_R">
    <collision>
      <origin rpy="0 0 0" xyz="0 0 0"/>
      <geometry>
        <mesh filename="package://mppi_controller/models/curiosity/meshes/suspension_steer_F_R_fixed.dae" scale="1.0 1.0 1.0"/>
      </geometry>
    </collision>
    <visual>
      <origin rpy="0 0 0" xyz="0 0 0"/>
      <geometry>
        <mesh filename="package://mppi_controller/models/curiosity/meshes/suspension_steer_F_R_fixed.dae" scale="1.0 1.0 1.0"/>
      </geometry>
    </visual>
    <inertial>
      <origin rpy="0 0 0" xyz="0 0 0"/>
      <mass value="7.295999999999999"/>
      <inertia ixx="0.150001040336768" ixy="0" ixz="0" iyy="0.2928966459341759" iyz="0" izz="0.19661828629500797"/>
    </inertial>
  </link>
  <joint name="suspension_steer_F_R_joint" type="revolute">
    <parent link="suspension_arm_F_R_to_suspension_steer_F_R"/>
    <child link="suspension_steer_F_R"/>
    <origin rpy="0 0 0" xyz="0 0 0"/>
    <limit effort="10000.0" lower="-0.6" upper="0.6" velocity="10.0"/>
    <axis xyz="0 0 1"/>
  </joint>
  <link name="suspension_steer_F_R_to_front_wheel_R">
    <inertial>
      <origin rpy="0 0 0" xyz="0 0 0"/>
      <mass value="0.02"/>
      <inertia ixx="2.61666666667e-05" ixy="0.0" ixz="0.0" iyy="2.61666666667e-05" iyz="0.0" izz="3.6e-05"/>
    </inertial>
    <collision>
      <origin rpy="0.0 1.57 0" xyz="0 0 0"/>
      <geometry>
        <cylinder length="0.02" radius="0.02"/>
      </geometry>
    </collision>
    <visual>
      <origin rpy="0.0 1.57 0" xyz="0 0 0"/>
      <geometry>
        <cylinder length="0.02" radius="0.02"/>
      </geometry>
    </visual>
  </link>
  <joint name="suspension_steer_F_R_to_suspension_steer_F_R_to_front_wheel_R_joint" type="fixed">
    <parent link="suspension_steer_F_R"/>
    <child link="suspension_steer_F_R_to_front_wheel_R"/>
    <origin rpy="0 0 0" xyz="0 0 -0.3996"/>
  </joint>
  <!-- tY is Zero if left side, 1 if right side -->
  <link name="front_wheel_R">
    <collision>
      <origin rpy="0 1.57 0" xyz="0 0 0"/>
      <geometry>
        <cylinder length="0.39473" radius="0.242647"/>
      </geometry>
    </collision>
    <visual>
      <origin rpy="0 0 0" xyz="0 0 0"/>
      <geometry>
        <mesh filename="package://mppi_controller/models/curiosity/meshes/wheel_fixed.dae" scale="1.0 1.0 1.0"/>
      </geometry>
    </visual>
    <inertial>
      <origin rpy="0 0 0" xyz="0 0 0"/>
      <mass value="2.07"/>
      <inertia ixx="0.05734667154540749" ixy="0" ixz="0" iyy="0.05734667154540749" iyz="0" izz="0.06093828144031499"/>
    </inertial>
  </link>
  <gazebo reference="front_wheel_R">
    <mu1 value="1.0"/>
    <mu2 value="1.0"/>
    <kp value="10000000.0"/>
    <kd>100.0</kd>
    <minDepth>0.001</minDepth>
    <maxVel>1.0</maxVel>
    <!--kd  value="1.0" />
      <fdir1 value="1 0 0"/-->
  </gazebo>
  <joint name="front_wheel_R_joint" type="continuous">
    <parent link="suspension_steer_F_R_to_front_wheel_R"/>
    <child link="front_wheel_R"/>
    <origin rpy="0 0 -3.141592653589793" xyz="0 0 0"/>
    <limit effort="10000.0" velocity="100.0"/>
    <axis xyz="1 0 0"/>
    <dynamics damping="0.0" friction="0.0"/>
  </joint>
  <!-- FRONT WHEEL RIGHT END -->
  <link name="suspension_arm_B2_R_to_middle_wheel_R">
    <inertial>
      <origin rpy="0 0 0" xyz="0 0 0"/>
      <mass value="0.02"/>
      <inertia ixx="2.61666666667e-05" ixy="0.0" ixz="0.0" iyy="2.61666666667e-05" iyz="0.0" izz="3.6e-05"/>
    </inertial>
    <collision>
      <origin rpy="0.0 1.57 0" xyz="0 0 0"/>
      <geometry>
        <cylinder length="0.02" radius="0.02"/>
      </geometry>
    </collision>
    <visual>
      <origin rpy="0.0 1.57 0" xyz="0 0 0"/>
      <geometry>
        <cylinder length="0.02" radius="0.02"/>
      </geometry>
    </visual>
  </link>
  <joint name="suspension_arm_B2_R_to_suspension_arm_B2_R_to_middle_wheel_R_joint" type="fixed">
    <parent link="suspension_arm_B2_R"/>
    <child link="suspension_arm_B2_R_to_middle_wheel_R"/>
    <origin rpy="0 0 0" xyz="-0.39423 -0.44859 -0.41098"/>
  </joint>
  <!-- tY is Zero if left side, 1 if right side -->
  <link name="middle_wheel_R">
    <collision>
      <origin rpy="0 1.57 0" xyz="0 0 0"/>
      <geometry>
        <cylinder length="0.39473" radius="0.242647"/>
      </geometry>
    </collision>
    <visual>
      <origin rpy="0 0 0" xyz="0 0 0"/>
      <geometry>
        <mesh filename="package://mppi_controller/models/curiosity/meshes/wheel_fixed.dae" scale="1.0 1.0 1.0"/>
      </geometry>
    </visual>
    <inertial>
      <origin rpy="0 0 0" xyz="0 0 0"/>
      <mass value="2.07"/>
      <inertia ixx="0.05734667154540749" ixy="0" ixz="0" iyy="0.05734667154540749" iyz="0" izz="0.06093828144031499"/>
    </inertial>
  </link>
  <gazebo reference="middle_wheel_R">
    <mu1 value="1.0"/>
    <mu2 value="1.0"/>
    <kp value="10000000.0"/>
    <kd>100.0</kd>
    <minDepth>0.001</minDepth>
    <maxVel>1.0</maxVel>
    <!--kd  value="1.0" />
      <fdir1 value="1 0 0"/-->
  </gazebo>
  <joint name="middle_wheel_R_joint" type="continuous">
    <parent link="suspension_arm_B2_R_to_middle_wheel_R"/>
    <child link="middle_wheel_R"/>
    <origin rpy="0 0 -3.141592653589793" xyz="0 0 0"/>
    <limit effort="10000.0" velocity="100.0"/>
    <axis xyz="1 0 0"/>
    <dynamics damping="0.0" friction="0.0"/>
  </joint>
  <!-- RIGHT BACK WHEEL -->
  <link name="suspension_arm_B2_R_to_suspension_steer_B_R">
    <inertial>
      <origin rpy="0 0 0" xyz="0 0 0"/>
      <mass value="0.02"/>
      <inertia ixx="2.61666666667e-05" ixy="0.0" ixz="0.0" iyy="2.61666666667e-05" iyz="0.0" izz="3.6e-05"/>
    </inertial>
    <collision>
      <origin rpy="0 0 0" xyz="0 0 0.015"/>
      <geometry>
        <cylinder length="0.04" radius="0.06"/>
      </geometry>
    </collision>
    <visual>
      <origin rpy="0.0 0 0" xyz="0 0 0"/>
      <geometry>
        <cylinder length="0.04" radius="0.06"/>
      </geometry>
    </visual>
  </link>
  <joint name="suspension_arm_B2_R_to_suspension_steer_B_R_joint" type="fixed">
    <parent link="suspension_arm_B2_R"/>
    <child link="suspension_arm_B2_R_to_suspension_steer_B_R"/>
    <origin rpy="0 0 0" xyz="-0.26271 0.62363 -0.00069"/>
  </joint>
  <link name="suspension_steer_B_R">
    <collision>
      <origin rpy="0 0 0" xyz="0 0 0"/>
      <geometry>
        <mesh filename="package://mppi_controller/models/curiosity/meshes/suspension_steer_B_R_fixed.dae" scale="1.0 1.0 1.0"/>
      </geometry>
    </collision>
    <visual>
      <origin rpy="0 0 0" xyz="0 0 0"/>
      <geometry>
        <mesh filename="package://mppi_controller/models/curiosity/meshes/suspension_steer_B_R_fixed.dae" scale="1.0 1.0 1.0"/>
      </geometry>
    </visual>
    <inertial>
      <origin rpy="0 0 0" xyz="0 0 0"/>
      <mass value="7.295999999999999"/>
      <inertia ixx="0.150001040336768" ixy="0" ixz="0" iyy="0.2928966459341759" iyz="0" izz="0.19661828629500797"/>
    </inertial>
  </link>
  <joint name="suspension_steer_B_R_joint" type="revolute">
    <parent link="suspension_arm_B2_R_to_suspension_steer_B_R"/>
    <child link="suspension_steer_B_R"/>
    <origin rpy="0 0 0" xyz="0 0 0"/>
    <limit effort="10000.0" lower="-0.6" upper="0.6" velocity="10.0"/>
    <axis xyz="0 0 1"/>
  </joint>
  <link name="suspension_steer_B_R_to_back_wheel_R">
    <inertial>
      <origin rpy="0 0 0" xyz="0 0 0"/>
      <mass value="0.02"/>
      <inertia ixx="2.61666666667e-05" ixy="0.0" ixz="0.0" iyy="2.61666666667e-05" iyz="0.0" izz="3.6e-05"/>
    </inertial>
    <collision>
      <origin rpy="0.0 1.57 0" xyz="0 0 0"/>
      <geometry>
        <cylinder length="0.02" radius="0.02"/>
      </geometry>
    </collision>
    <visual>
      <origin rpy="0.0 1.57 0" xyz="0 0 0"/>
      <geometry>
        <cylinder length="0.02" radius="0.02"/>
      </geometry>
    </visual>
  </link>
  <joint name="suspension_arm_B2_R_to_suspension_steer_B_R_to_back_wheel_R_joint" type="fixed">
    <parent link="suspension_steer_B_R"/>
    <child link="suspension_steer_B_R_to_back_wheel_R"/>
    <origin rpy="0 0 0" xyz="0 0 -0.410523"/>
  </joint>
  <!-- tY is Zero if left side, 1 if right side -->
  <link name="back_wheel_R">
    <collision>
      <origin rpy="0 1.57 0" xyz="0 0 0"/>
      <geometry>
        <cylinder length="0.39473" radius="0.242647"/>
      </geometry>
    </collision>
    <visual>
      <origin rpy="0 0 0" xyz="0 0 0"/>
      <geometry>
        <mesh filename="package://mppi_controller/models/curiosity/meshes/wheel_fixed.dae" scale="1.0 1.0 1.0"/>
      </geometry>
    </visual>
    <inertial>
      <origin rpy="0 0 0" xyz="0 0 0"/>
      <mass value="2.07"/>
      <inertia ixx="0.05734667154540749" ixy="0" ixz="0" iyy="0.05734667154540749" iyz="0" izz="0.06093828144031499"/>
    </inertial>
  </link>
  <gazebo reference="back_wheel_R">
    <mu1 value="1.0"/>
    <mu2 value="1.0"/>
    <kp value="10000000.0"/>
    <kd>100.0</kd>
    <minDepth>0.001</minDepth>
    <maxVel>1.0</maxVel>
    <!--kd  value="1.0" />
      <fdir1 value="1 0 0"/-->
  </gazebo>
  <joint name="back_wheel_R_joint" type="continuous">
    <parent link="suspension_steer_B_R_to_back_wheel_R"/>
    <child link="back_wheel_R"/>
    <origin rpy="0 0 -3.141592653589793" xyz="0 0 0"/>
    <limit effort="10000.0" velocity="100.0"/>
    <axis xyz="1 0 0"/>
    <dynamics damping="0.0" friction="0.0"/>
  </joint>
  <!-- END BACK WHEEL RIGHT -->
  <link name="chassis_to_arm_01">
    <inertial>
      <origin rpy="0 0 0" xyz="0 0 0"/>
      <mass value="0.02"/>
      <inertia ixx="2.61666666667e-05" ixy="0.0" ixz="0.0" iyy="2.61666666667e-05" iyz="0.0" izz="3.6e-05"/>
    </inertial>
    <collision>
      <origin rpy="0.0 1.57 0" xyz="0 0 0"/>
      <geometry>
        <cylinder length="0.02" radius="0.02"/>
      </geometry>
    </collision>
    <visual>
      <origin rpy="0.0 0 0" xyz="0 0 0"/>
      <geometry>
        <cylinder length="0.02" radius="0.02"/>
      </geometry>
    </visual>
  </link>
  <joint name="chassis_to_arm_01_joint" type="fixed">
    <parent link="chassis"/>
    <child link="chassis_to_arm_01"/>
    <origin rpy="0 0 0" xyz="0.449641 -1.11319 0.112807"/>
  </joint>
  <link name="arm_01">
    <collision>
      <origin rpy="0 0 0" xyz="0 0 0"/>
      <geometry>
        <mesh filename="package://mppi_controller/models/curiosity/meshes/arm_01_fixed.dae" scale="1.0 1.0 1.0"/>
      </geometry>
    </collision>
    <visual>
      <origin rpy="0 0 0" xyz="0 0 0"/>
      <geometry>
        <mesh filename="package://mppi_controller/models/curiosity/meshes/arm_01_fixed.dae" scale="1.0 1.0 1.0"/>
      </geometry>
    </visual>
    <inertial>
      <origin rpy="0 0 0" xyz="0 0 0"/>
      <mass value="6.0"/>
      <inertia ixx="0.10097419075249998" ixy="0" ixz="0" iyy="0.108839023501" iyz="0" izz="0.1195063531325"/>
    </inertial>
  </link>
  <joint name="arm_01_joint" type="revolute">
    <parent link="chassis_to_arm_01"/>
    <child link="arm_01"/>
    <origin rpy="0 0 0" xyz="0 0 0"/>
    <limit effort="10000.0" lower="-1.57" upper="1.57" velocity="100.0"/>
    <axis xyz="0 0 1"/>
    <dynamics damping="0.0" friction="0.0"/>
  </joint>
  <link name="arm_01_to_arm_02">
    <inertial>
      <origin rpy="0 0 0" xyz="0 0 0"/>
      <mass value="0.02"/>
      <inertia ixx="2.61666666667e-05" ixy="0.0" ixz="0.0" iyy="2.61666666667e-05" iyz="0.0" izz="3.6e-05"/>
    </inertial>
    <collision>
      <origin rpy="0.0 1.57 0" xyz="0 0 0"/>
      <geometry>
        <cylinder length="0.02" radius="0.02"/>
      </geometry>
    </collision>
    <visual>
      <origin rpy="0.0 0 0" xyz="0 0 0"/>
      <geometry>
        <cylinder length="0.02" radius="0.02"/>
      </geometry>
    </visual>
  </link>
  <joint name="arm_01_to_arm_02_joint" type="fixed">
    <parent link="arm_01"/>
    <child link="arm_01_to_arm_02"/>
    <origin rpy="0 0 0" xyz="0.0 -0.160259 -0.166117"/>
  </joint>
  <link name="arm_02">
    <collision>
      <origin rpy="0 0 0" xyz="0 0 0"/>
      <geometry>
        <mesh filename="package://mppi_controller/models/curiosity/meshes/arm_01_fixed.dae" scale="1.0 1.0 1.0"/>
      </geometry>
    </collision>
    <visual>
      <origin rpy="0 0 0" xyz="0 0 0"/>
      <geometry>
        <mesh filename="package://mppi_controller/models/curiosity/meshes/arm_02_fixed.dae" scale="1.0 1.0 1.0"/>
      </geometry>
    </visual>
    <inertial>
      <origin rpy="0 0 0" xyz="0 0 0"/>
      <mass value="6.0"/>
      <inertia ixx="0.49659166964500007" ixy="0" ixz="0" iyy="0.13536811128100001" iyz="0" izz="0.584169011605"/>
    </inertial>
  </link>
  <joint name="arm_02_joint" type="revolute">
    <parent link="arm_01_to_arm_02"/>
    <child link="arm_02"/>
    <origin rpy="0 0 0" xyz="0 0 0"/>
    <limit effort="10000.0" lower="-1.57" upper="1.57" velocity="100.0"/>
    <axis xyz="1 0 0"/>
    <dynamics damping="0.0" friction="0.0"/>
  </joint>
  <link name="arm_02_to_arm_03">
    <inertial>
      <origin rpy="0 0 0" xyz="0 0 0"/>
      <mass value="0.02"/>
      <inertia ixx="2.61666666667e-05" ixy="0.0" ixz="0.0" iyy="2.61666666667e-05" iyz="0.0" izz="3.6e-05"/>
    </inertial>
    <collision>
      <origin rpy="0.0 1.57 0" xyz="0 0 0"/>
      <geometry>
        <cylinder length="0.02" radius="0.02"/>
      </geometry>
    </collision>
    <visual>
      <origin rpy="0.0 0 0" xyz="0 0 0"/>
      <geometry>
        <cylinder length="0.02" radius="0.02"/>
      </geometry>
    </visual>
  </link>
  <joint name="arm_02_to_arm_03_joint" type="fixed">
    <parent link="arm_02"/>
    <child link="arm_02_to_arm_03"/>
    <origin rpy="0 0 0" xyz="0.071249 -0.825069 0.0"/>
  </joint>
  <link name="arm_03">
    <collision>
      <origin rpy="0 0 0" xyz="0 0 0"/>
      <geometry>
        <mesh filename="package://mppi_controller/models/curiosity/meshes/arm_03_fixed.dae" scale="1.0 1.0 1.0"/>
      </geometry>
    </collision>
    <visual>
      <origin rpy="0 0 0" xyz="0 0 0"/>
      <geometry>
        <mesh filename="package://mppi_controller/models/curiosity/meshes/arm_03_fixed.dae" scale="1.0 1.0 1.0"/>
      </geometry>
    </visual>
    <inertial>
      <origin rpy="0 0 0" xyz="0 0 0"/>
      <mass value="6.0"/>
      <inertia ixx="0.40223381310649997" ixy="0" ixz="0" iyy="0.43335590733199997" iyz="0" izz="0.06302255467449999"/>
    </inertial>
  </link>
  <joint name="arm_03_joint" type="revolute">
    <parent link="arm_02_to_arm_03"/>
    <child link="arm_03"/>
    <origin rpy="0 0 0" xyz="0 0 0"/>
    <limit effort="10000.0" lower="-5.0" upper="5.0" velocity="100.0"/>
    <axis xyz="1 0 0"/>
    <dynamics damping="0.0" friction="0.0"/>
  </joint>
  <link name="arm_03_to_arm_04">
    <inertial>
      <origin rpy="0 0 0" xyz="0 0 0"/>
      <mass value="0.02"/>
      <inertia ixx="2.61666666667e-05" ixy="0.0" ixz="0.0" iyy="2.61666666667e-05" iyz="0.0" izz="3.6e-05"/>
    </inertial>
    <collision>
      <origin rpy="1.57 0 0" xyz="0 0 0"/>
      <geometry>
        <cylinder length="0.02" radius="0.02"/>
      </geometry>
    </collision>
    <visual>
      <origin rpy="1.57 0 0" xyz="0 0 0"/>
      <geometry>
        <cylinder length="0.02" radius="0.02"/>
      </geometry>
    </visual>
  </link>
  <joint name="arm_03_to_arm_04_joint" type="fixed">
    <parent link="arm_03"/>
    <child link="arm_03_to_arm_04"/>
    <origin rpy="0 0 1.5707963267948966" xyz="-0.193815 0.0 0.779746"/>
  </joint>
  <link name="arm_04">
    <collision>
      <origin rpy="0 0 0" xyz="0 0 0"/>
      <geometry>
        <mesh filename="package://mppi_controller/models/curiosity/meshes/arm_04_fixed.dae" scale="1.0 1.0 1.0"/>
      </geometry>
    </collision>
    <visual>
      <origin rpy="0 0 0" xyz="0 0 0"/>
      <geometry>
        <mesh filename="package://mppi_controller/models/curiosity/meshes/arm_04_fixed.dae" scale="1.0 1.0 1.0"/>
      </geometry>
    </visual>
    <inertial>
      <origin rpy="0 0 0" xyz="0 0 0"/>
      <mass value="6.0"/>
      <inertia ixx="0.10111859423649999" ixy="0" ixz="0" iyy="0.09436857731199999" iyz="0" izz="0.1120632473245"/>
    </inertial>
  </link>
  <joint name="arm_04_joint" type="revolute">
    <parent link="arm_03_to_arm_04"/>
    <child link="arm_04"/>
    <origin rpy="0 0 0" xyz="0 0 0"/>
    <limit effort="10000.0" lower="-1.57" upper="1.57" velocity="100.0"/>
    <axis xyz="0 1 0"/>
    <dynamics damping="0.0" friction="0.0"/>
  </joint>
  <link name="arm_04_to_arm_tools">
    <inertial>
      <origin rpy="0 0 0" xyz="0 0 0"/>
      <mass value="0.02"/>
      <inertia ixx="2.61666666667e-05" ixy="0.0" ixz="0.0" iyy="2.61666666667e-05" iyz="0.0" izz="3.6e-05"/>
    </inertial>
    <collision>
      <origin rpy="0 0 0" xyz="0 0 0"/>
      <geometry>
        <cylinder length="0.02" radius="0.02"/>
      </geometry>
    </collision>
    <visual>
      <origin rpy="0 0 0" xyz="0 0 0"/>
      <geometry>
        <cylinder length="0.02" radius="0.02"/>
      </geometry>
    </visual>
  </link>
  <joint name="arm_04_to_arm_tools_joint" type="fixed">
    <parent link="arm_04"/>
    <child link="arm_04_to_arm_tools"/>
    <origin rpy="0 0 0" xyz="0.141321 0.042652 0.105732"/>
  </joint>
  <link name="arm_tools">
    <collision>
      <origin rpy="0 0 0" xyz="0 0 0"/>
      <geometry>
        <mesh filename="package://mppi_controller/models/curiosity/meshes/arm_tools_fixed.dae" scale="1.0 1.0 1.0"/>
      </geometry>
    </collision>
    <visual>
      <origin rpy="0 0 0" xyz="0 0 0"/>
      <geometry>
        <mesh filename="package://mppi_controller/models/curiosity/meshes/arm_tools_fixed.dae" scale="1.0 1.0 1.0"/>
      </geometry>
    </visual>
    <inertial>
      <origin rpy="0 0 0" xyz="0 0 0"/>
      <mass value="6.0"/>
      <inertia ixx="0.1331265210545" ixy="0" ixz="0" iyy="0.20570933745" iyz="0" izz="0.29080913600450004"/>
    </inertial>
  </link>
  <joint name="arm_tools_joint" type="continuous">
    <parent link="arm_04_to_arm_tools"/>
    <child link="arm_tools"/>
    <origin rpy="0 0 0" xyz="0 0 0"/>
    <limit effort="10000.0" velocity="100.0"/>
    <axis xyz="0 0 1"/>
    <dynamics damping="0.0" friction="0.0"/>
  </joint>
  <link name="chassis_to_mast_p">
    <inertial>
      <origin rpy="0 0 0" xyz="0 0 0"/>
      <mass value="0.02"/>
      <inertia ixx="2.61666666667e-05" ixy="0.0" ixz="0.0" iyy="2.61666666667e-05" iyz="0.0" izz="3.6e-05"/>
    </inertial>
    <collision>
      <origin rpy="1.57 0 0" xyz="0 0 0"/>
      <geometry>
        <cylinder length="0.02" radius="0.02"/>
      </geometry>
    </collision>
    <visual>
      <origin rpy="1.57 0 0" xyz="0 0 0"/>
      <geometry>
        <cylinder length="0.02" radius="0.02"/>
      </geometry>
    </visual>
  </link>
  <joint name="chassis_to_mast_p_joint" type="fixed">
    <parent link="chassis"/>
    <child link="chassis_to_mast_p"/>
    <origin rpy="0 0 0.523599" xyz="-0.55456 -0.722499 0.331395"/>
  </joint>
  <link name="mast_p">
    <collision>
      <origin rpy="0 0 0" xyz="0 0 0"/>
      <geometry>
        <mesh filename="package://mppi_controller/models/curiosity/meshes/mast_p_fixed.dae" scale="1.0 1.0 1.0"/>
      </geometry>
    </collision>
    <visual>
      <origin rpy="0 0 0" xyz="0 0 0"/>
      <geometry>
        <mesh filename="package://mppi_controller/models/curiosity/meshes/mast_p_fixed.dae" scale="1.0 1.0 1.0"/>
      </geometry>
    </visual>
    <inertial>
      <origin rpy="0 0 0" xyz="0 0 0"/>
      <mass value="16.666666666666668"/>
      <inertia ixx="0.45185698288472226" ixy="0" ixz="0" iyy="0.4350648982180556" iyz="0" izz="0.11948455987777779"/>
    </inertial>
  </link>
  <joint name="mast_p_joint" type="revolute">
    <parent link="chassis_to_mast_p"/>
    <child link="mast_p"/>
    <origin rpy="0 0 0" xyz="0 0 0"/>
    <limit effort="10000.0" lower="0.0" upper="1.57" velocity="100.0"/>
    <axis xyz="0 1 0"/>
    <dynamics damping="0.0" friction="0.0"/>
  </joint>
  <link name="mast_p_to_mast_02">
    <inertial>
      <origin rpy="0 0 0" xyz="0 0 0"/>
      <mass value="0.02"/>
      <inertia ixx="2.61666666667e-05" ixy="0.0" ixz="0.0" iyy="2.61666666667e-05" iyz="0.0" izz="3.6e-05"/>
    </inertial>
    <collision>
      <origin rpy="0 0 0" xyz="0 0 0"/>
      <geometry>
        <cylinder length="0.02" radius="0.02"/>
      </geometry>
    </collision>
    <visual>
      <origin rpy="0 0 0" xyz="0 0 0"/>
      <geometry>
        <cylinder length="0.02" radius="0.02"/>
      </geometry>
    </visual>
  </link>
  <joint name="mast_p_to_mast_02_joint" type="fixed">
    <parent link="mast_p"/>
    <child link="mast_p_to_mast_02"/>
    <origin rpy="0 0 0" xyz="0 0 0.473641"/>
  </joint>
  <link name="mast_02">
    <collision>
      <origin rpy="0 0 0" xyz="0 0 0"/>
      <geometry>
        <mesh filename="package://mppi_controller/models/curiosity/meshes/mast_02_fixed.dae" scale="1.0 1.0 1.0"/>
      </geometry>
    </collision>
    <visual>
      <origin rpy="0 0 0" xyz="0 0 0"/>
      <geometry>
        <mesh filename="package://mppi_controller/models/curiosity/meshes/mast_02_fixed.dae" scale="1.0 1.0 1.0"/>
      </geometry>
    </visual>
    <inertial>
      <origin rpy="0 0 0" xyz="0 0 0"/>
      <mass value="16.666666666666668"/>
      <inertia ixx="0.18840199059027782" ixy="0" ixz="0" iyy="0.21556002770138893" iyz="0" izz="0.1767890389138889"/>
    </inertial>
  </link>
  <joint name="mast_02_joint" type="continuous">
    <parent link="mast_p_to_mast_02"/>
    <child link="mast_02"/>
    <origin rpy="0 0 0" xyz="0 0 0"/>
    <limit effort="10000.0" velocity="100.0"/>
    <axis xyz="0 0 1"/>
    <dynamics damping="0.0" friction="0.0"/>
  </joint>
  <link name="mast_02_to_mast_cameras">
    <inertial>
      <origin rpy="0 0 0" xyz="0 0 0"/>
      <mass value="0.02"/>
      <inertia ixx="2.61666666667e-05" ixy="0.0" ixz="0.0" iyy="2.61666666667e-05" iyz="0.0" izz="3.6e-05"/>
    </inertial>
    <collision>
      <origin rpy="0 0 0" xyz="0 0 0"/>
      <geometry>
        <cylinder length="0.02" radius="0.02"/>
      </geometry>
    </collision>
    <visual>
      <origin rpy="0 0 0" xyz="0 0 0"/>
      <geometry>
        <cylinder length="0.02" radius="0.02"/>
      </geometry>
    </visual>
  </link>
  <joint name="mast_02_to_mast_cameras_joint" type="fixed">
    <parent link="mast_02"/>
    <child link="mast_02_to_mast_cameras"/>
    <origin rpy="0 0 0" xyz="0 0 0.20859"/>
  </joint>
  <link name="mast_cameras">
    <collision>
      <origin rpy="0 0 0" xyz="0 0 0"/>
      <geometry>
        <mesh filename="package://mppi_controller/models/curiosity/meshes/mast_cameras.dae" scale="1.0 1.0 1.0"/>
      </geometry>
    </collision>
    <visual>
      <origin rpy="0 0 0" xyz="0 0 0"/>
      <geometry>
        <mesh filename="package://mppi_controller/models/curiosity/meshes/mast_cameras.dae" scale="1.0 1.0 1.0"/>
      </geometry>
    </visual>
    <inertial>
      <origin rpy="0 0 0" xyz="0 0 0"/>
      <mass value="16.666666666666668"/>
      <inertia ixx="0.16903210838472227" ixy="0" ixz="0" iyy="0.4779370167180556" iyz="0" izz="0.5313759250027777"/>
    </inertial>
  </link>
  <joint name="mast_cameras_joint" type="revolute">
    <parent link="mast_02_to_mast_cameras"/>
    <child link="mast_cameras"/>
    <origin rpy="0 0 0" xyz="0 0 0"/>
    <limit effort="10000.0" lower="-1.57" upper="1.57" velocity="100.0"/>
    <axis xyz="1 0 0"/>
    <dynamics damping="0.0" friction="0.0"/>
  </joint>
  <material name="green">
    <color rgba="0 0.8 0 1"/>
  </material>
  <link name="camera_link">
    <!-- Inertial for gazebo to take it into account, Put 1gr weight -->
    <inertial>
      <origin rpy="0 0 0" xyz="0 0 0"/>
      <mass value="0.001"/>
      <inertia ixx="9.1875e-09" ixy="0.0" ixz="0.0" iyy="9.1875e-09" iyz="0.0" izz="1.378125e-08"/>
    </inertial>
    <visual>
      <origin rpy="0.0 0 0" xyz="0 0 0"/>
      <geometry>
        <box size="0.0005 0.0005 0.0005"/>
      </geometry>
      <material name="green"/>
    </visual>
  </link>
  <gazebo reference="camera_link">
    <material>Gazebo/Green</material>
  </gazebo>
  <joint name="head_camera_joint" type="fixed">
    <parent link="mast_cameras"/>
    <child link="camera_link"/>
    <origin rpy="0 0 -1.5707963267948966" xyz="0.13642 -0.218683 0.222314"/>
  </joint>
  <link name="lidar_link">
    <!-- Inertial for gazebo to take it into account, Put 1gr weight -->
    <inertial>
      <origin rpy="0 0 0" xyz="0 0 0"/>
      <mass value="0.001"/>
      <inertia ixx="9.1875e-09" ixy="0.0" ixz="0.0" iyy="9.1875e-09" iyz="0.0" izz="1.378125e-08"/>
    </inertial>
    <visual>
      <origin rpy="0.0 0 0" xyz="0 0 0"/>
      <geometry>
        <cylinder length="0.02" radius="0.05"/>
      </geometry>
      <material name="black"/>
    </visual>
  </link>
  <gazebo reference="lidar_link">
    <material>Gazebo/Black</material>
  </gazebo>
  <joint name="lidar_joint" type="fixed">
    <parent link="mast_cameras"/>
    <child link="lidar_link"/>
    <origin rpy="0 0 -1.5707963267948966" xyz="0 0 0.325"/>
  </joint>
</robot>
